Workbook

Sheet Dashboard
B2: 2026 Annual Dashboard สรุปผลรายปี พ.ศ. 2569 | G2: Total Income (รายได้ทั้งปี)
G3: =C21
B6: คลิกแท็บด้านล่างเพื่อไปแต่ละเดือน ↓ | G6: Total Expense (รายจ่ายทั้งปี)
G7: =D21
B8: เดือน | C8: รายได้ | D8: รายจ่าย | E8: คงเหลือ
B9: ม.ค. | C9: ='ม.ค.'!E5 | D9: ='ม.ค.'!E6 | E9: =C9-D9
B10: ก.พ. | C10: ='ก.พ.'!E5 | D10: ='ก.พ.'!E6 | E10: =C10-D10 | G10: Remaining (คงเหลือทั้งปี)
B11: มี.ค. | C11: ='มี.ค.'!E5 | D11: ='มี.ค.'!E6 | E11: =C11-D11 | G11: =E21
B12: เม.ย. | C12: ='เม.ย.'!E5 | D12: ='เม.ย.'!E6 | E12: =C12-D12
B13: พ.ค. | C13: ='พ.ค.'!E5 | D13: ='พ.ค.'!E6 | E13: =C13-D13
B14: มิ.ย. | C14: ='มิ.ย.'!E5 | D14: ='มิ.ย.'!E6 | E14: =C14-D14
B15: ก.ค. | C15: ='ก.ค.'!E5 | D15: ='ก.ค.'!E6 | E15: =C15-D15
B16: ส.ค. | C16: ='ส.ค.'!E5 | D16: ='ส.ค.'!E6 | E16: =C16-D16
B17: ก.ย. | C17: ='ก.ย.'!E5 | D17: ='ก.ย.'!E6 | E17: =C17-D17
B18: ต.ค. | C18: ='ต.ค.'!E5 | D18: ='ต.ค.'!E6 | E18: =C18-D18
B19: พ.ย. | C19: ='พ.ย.'!E5 | D19: ='พ.ย.'!E6 | E19: =C19-D19
B20: ธ.ค. | C20: ='ธ.ค.'!E5 | D20: ='ธ.ค.'!E6 | E20: =C20-D20
B21: รวมทั้งปี | C21: =SUM(C9:C20) | D21: =SUM(D9:D20) | E21: =C21-D21

Sheet ม.ค.
B2: มกราคม 2569
B4: ยอดยกมา (ต้นเดือน) | E4: 0 | H4: หมวด | I4: งบ | J4: จริง
B5: รายได้รวม (จริง) | E5: =D17 | H5: รายจ่ายประจำวัน | I5: =C31 | J5: =D31
B6: รายจ่ายรวม (รวมออม) | E6: =D31+D47+D56+D60 | H6: ค่ารายเดือน/หนี้ | I6: =C47 | J6: =D47
B7: คงเหลือสิ้นเดือน | E7: =E4+E5-E6 | H7: การลงทุน | I7: =C56 | J7: =D56
B9: รายได้ (Income)
B10: ประเภท | C10: เป้าหมาย | D10: จริง | E10: ส่วนต่าง
C11: 0 | D11: 0 | E11: =D11-C11
E12: =D12-C12
E13: =D13-C13
E14: =D14-C14
E15: =D15-C15
E16: =D16-C16
B17: รวมรายได้ | C17: =SUM(C11:C16) | D17: =SUM(D11:D16) | E17: =D17-C17
B19: รายจ่ายประจำวัน (Daily Expense)
B20: รายการ | C20: งบ (Budget) | D20: จริง (Actual) | E20: ส่วนต่าง
E21: =C21-D21
E22: =C22-D22
E23: =C23-D23
E24: =C24-D24
E25: =C25-D25
E26: =C26-D26
E27: =C27-D27
E28: =C28-D28
E29: =C29-D29
E30: =C30-D30
B31: รวม | C31: =SUM(C21:C30) | D31: =SUM(D21:D30) | E31: =C31-D31
B33: ค่ารายเดือน / ค่าหนี้ (Subscription / Debt)
B34: รายการ | C34: งบ (Budget) | D34: จริง (Actual) | E34: ส่วนต่าง
E35: =C35-D35
E36: =C36-D36
E37: =C37-D37
E38: =C38-D38
E39: =C39-D39
E40: =C40-D40
E41: =C41-D41
E42: =C42-D42
E43: =C43-D43
E44: =C44-D44
E45: =C45-D45
...

Sheet ก.พ.
B2: กุมภาพันธ์ 2569
B4: ยอดยกมา (ต้นเดือน) | E4: 0 | H4: หมวด | I4: งบ | J4: จริง
B5: รายได้รวม (จริง) | E5: =D17 | H5: รายจ่ายประจำวัน | I5: =C31 | J5: =D31
B6: รายจ่ายรวม (รวมออม) | E6: =D31+D47+D56+D60 | H6: ค่ารายเดือน/หนี้ | I6: =C47 | J6: =D47
B7: คงเหลือสิ้นเดือน | E7: =E4+E5-E6 | H7: การลงทุน | I7: =C56 | J7: =D56
B9: รายได้ (Income)
B10: ประเภท | C10: เป้าหมาย | D10: จริง | E10: ส่วนต่าง
C11: 0 | D11: 0 | E11: =D11-C11
E12: =D12-C12
E13: =D13-C13
E14: =D14-C14
E15: =D15-C15
E16: =D16-C16
B17: รวมรายได้ | C17: =SUM(C11:C16) | D17: =SUM(D11:D16) | E17: =D17-C17
B19: รายจ่ายประจำวัน (Daily Expense)
B20: รายการ | C20: งบ (Budget) | D20: จริง (Actual) | E20: ส่วนต่าง
E21: =C21-D21
E22: =C22-D22
E23: =C23-D23
E24: =C24-D24
E25: =C25-D25
E26: =C26-D26
E27: =C27-D27
E28: =C28-D28
E29: =C29-D29
E30: =C30-D30
B31: รวม | C31: =SUM(C21:C30) | D31: =SUM(D21:D30) | E31: =C31-D31
B33: ค่ารายเดือน / ค่าหนี้ (Subscription / Debt)
B34: รายการ | C34: งบ (Budget) | D34: จริง (Actual) | E34: ส่วนต่าง
E35: =C35-D35
E36: =C36-D36
E37: =C37-D37
E38: =C38-D38
E39: =C39-D39
E40: =C40-D40
E41: =C41-D41
E42: =C42-D42
E43: =C43-D43
E44: =C44-D44
E45: =C45-D45
...

Sheet มี.ค.
B2: มีนาคม 2569
B4: ยอดยกมา (ต้นเดือน) | E4: 0 | H4: หมวด | I4: งบ | J4: จริง
B5: รายได้รวม (จริง) | E5: =D17 | H5: รายจ่ายประจำวัน | I5: =C31 | J5: =D31
B6: รายจ่ายรวม (รวมออม) | E6: =D31+D47+D56+D60 | H6: ค่ารายเดือน/หนี้ | I6: =C47 | J6: =D47
B7: คงเหลือสิ้นเดือน | E7: =E4+E5-E6 | H7: การลงทุน | I7: =C56 | J7: =D56
B9: รายได้ (Income)
B10: ประเภท | C10: เป้าหมาย | D10: จริง | E10: ส่วนต่าง
C11: 0 | D11: 0 | E11: =D11-C11
E12: =D12-C12
E13: =D13-C13
E14: =D14-C14
E15: =D15-C15
E16: =D16-C16
B17: รวมรายได้ | C17: =SUM(C11:C16) | D17: =SUM(D11:D16) | E17: =D17-C17
B19: รายจ่ายประจำวัน (Daily Expense)
B20: รายการ | C20: งบ (Budget) | D20: จริง (Actual) | E20: ส่วนต่าง
E21: =C21-D21
E22: =C22-D22
E23: =C23-D23
E24: =C24-D24
E25: =C25-D25
E26: =C26-D26
E27: =C27-D27
E28: =C28-D28
E29: =C29-D29
E30: =C30-D30
B31: รวม | C31: =SUM(C21:C30) | D31: =SUM(D21:D30) | E31: =C31-D31
B33: ค่ารายเดือน / ค่าหนี้ (Subscription / Debt)
B34: รายการ | C34: งบ (Budget) | D34: จริง (Actual) | E34: ส่วนต่าง
E35: =C35-D35
E36: =C36-D36
E37: =C37-D37
E38: =C38-D38
E39: =C39-D39
E40: =C40-D40
E41: =C41-D41
E42: =C42-D42
E43: =C43-D43
E44: =C44-D44
E45: =C45-D45
...

Sheet เม.ย.
B2: เมษายน 2569
B4: ยอดยกมา (ต้นเดือน) | E4: 0 | H4: หมวด | I4: งบ | J4: จริง
B5: รายได้รวม (จริง) | E5: =D17 | H5: รายจ่ายประจำวัน | I5: =C31 | J5: =D31
B6: รายจ่ายรวม (รวมออม) | E6: =D31+D47+D56+D60 | H6: ค่ารายเดือน/หนี้ | I6: =C47 | J6: =D47
B7: คงเหลือสิ้นเดือน | E7: =E4+E5-E6 | H7: การลงทุน | I7: =C56 | J7: =D56
B9: รายได้ (Income)
B10: ประเภท | C10: เป้าหมาย | D10: จริง | E10: ส่วนต่าง
C11: 0 | D11: 0 | E11: =D11-C11
E12: =D12-C12
E13: =D13-C13
E14: =D14-C14
E15: =D15-C15
E16: =D16-C16
B17: รวมรายได้ | C17: =SUM(C11:C16) | D17: =SUM(D11:D16) | E17: =D17-C17
B19: รายจ่ายประจำวัน (Daily Expense)
B20: รายการ | C20: งบ (Budget) | D20: จริง (Actual) | E20: ส่วนต่าง
E21: =C21-D21
E22: =C22-D22
E23: =C23-D23
E24: =C24-D24
E25: =C25-D25
E26: =C26-D26
E27: =C27-D27
E28: =C28-D28
E29: =C29-D29
E30: =C30-D30
B31: รวม | C31: =SUM(C21:C30) | D31: =SUM(D21:D30) | E31: =C31-D31
B33: ค่ารายเดือน / ค่าหนี้ (Subscription / Debt)
B34: รายการ | C34: งบ (Budget) | D34: จริง (Actual) | E34: ส่วนต่าง
E35: =C35-D35
E36: =C36-D36
E37: =C37-D37
E38: =C38-D38
E39: =C39-D39
E40: =C40-D40
E41: =C41-D41
E42: =C42-D42
E43: =C43-D43
E44: =C44-D44
E45: =C45-D45
...

Sheet พ.ค.
B2: พฤษภาคม 2569
B4: ยอดยกมา (ต้นเดือน) | E4: 0 | H4: หมวด | I4: งบ | J4: จริง
B5: รายได้รวม (จริง) | E5: =D17 | H5: รายจ่ายประจำวัน | I5: =C31 | J5: =D31
B6: รายจ่ายรวม (รวมออม) | E6: =D31+D47+D56+D60 | H6: ค่ารายเดือน/หนี้ | I6: =C47 | J6: =D47
B7: คงเหลือสิ้นเดือน | E7: =E4+E5-E6 | H7: การลงทุน | I7: =C56 | J7: =D56
B9: รายได้ (Income)
B10: ประเภท | C10: เป้าหมาย | D10: จริง | E10: ส่วนต่าง
C11: 0 | D11: 0 | E11: =D11-C11
E12: =D12-C12
E13: =D13-C13
E14: =D14-C14
E15: =D15-C15
E16: =D16-C16
B17: รวมรายได้ | C17: =SUM(C11:C16) | D17: =SUM(D11:D16) | E17: =D17-C17
B19: รายจ่ายประจำวัน (Daily Expense)
B20: รายการ | C20: งบ (Budget) | D20: จริง (Actual) | E20: ส่วนต่าง
E21: =C21-D21
E22: =C22-D22
E23: =C23-D23
E24: =C24-D24
E25: =C25-D25
E26: =C26-D26
E27: =C27-D27
E28: =C28-D28
E29: =C29-D29
E30: =C30-D30
B31: รวม | C31: =SUM(C21:C30) | D31: =SUM(D21:D30) | E31: =C31-D31
B33: ค่ารายเดือน / ค่าหนี้ (Subscription / Debt)
B34: รายการ | C34: งบ (Budget) | D34: จริง (Actual) | E34: ส่วนต่าง
E35: =C35-D35
E36: =C36-D36
E37: =C37-D37
E38: =C38-D38
E39: =C39-D39
E40: =C40-D40
E41: =C41-D41
E42: =C42-D42
E43: =C43-D43
E44: =C44-D44
E45: =C45-D45
...

Sheet มิ.ย.
B2: มิถุนายน 2569
B4: ยอดยกมา (ต้นเดือน) | E4: 0 | H4: หมวด | I4: งบ | J4: จริง
B5: รายได้รวม (จริง) | E5: =D17 | H5: รายจ่ายประจำวัน | I5: =C31 | J5: =D31
B6: รายจ่ายรวม (รวมออม) | E6: =D31+D47+D56+D60 | H6: ค่ารายเดือน/หนี้ | I6: =C47 | J6: =D47
B7: คงเหลือสิ้นเดือน | E7: =E4+E5-E6 | H7: การลงทุน | I7: =C56 | J7: =D56
B9: รายได้ (Income)
B10: ประเภท | C10: เป้าหมาย | D10: จริง | E10: ส่วนต่าง
C11: 0 | D11: 0 | E11: =D11-C11
E12: =D12-C12
E13: =D13-C13
E14: =D14-C14
E15: =D15-C15
E16: =D16-C16
B17: รวมรายได้ | C17: =SUM(C11:C16) | D17: =SUM(D11:D16) | E17: =D17-C17
B19: รายจ่ายประจำวัน (Daily Expense)
B20: รายการ | C20: งบ (Budget) | D20: จริง (Actual) | E20: ส่วนต่าง
E21: =C21-D21
E22: =C22-D22
E23: =C23-D23
E24: =C24-D24
E25: =C25-D25
E26: =C26-D26
E27: =C27-D27
E28: =C28-D28
E29: =C29-D29
E30: =C30-D30
B31: รวม | C31: =SUM(C21:C30) | D31: =SUM(D21:D30) | E31: =C31-D31
B33: ค่ารายเดือน / ค่าหนี้ (Subscription / Debt)
B34: รายการ | C34: งบ (Budget) | D34: จริง (Actual) | E34: ส่วนต่าง
E35: =C35-D35
E36: =C36-D36
E37: =C37-D37
E38: =C38-D38
E39: =C39-D39
E40: =C40-D40
E41: =C41-D41
E42: =C42-D42
E43: =C43-D43
E44: =C44-D44
E45: =C45-D45
...

Sheet ก.ค.
B2: กรกฎาคม 2569
B4: ยอดยกมา (ต้นเดือน) | E4: 0 | H4: หมวด | I4: งบ | J4: จริง
B5: รายได้รวม (จริง) | E5: =D17 | H5: รายจ่ายประจำวัน | I5: =C31 | J5: =D31
B6: รายจ่ายรวม (รวมออม) | E6: =D31+D47+D56+D60 | H6: ค่ารายเดือน/หนี้ | I6: =C47 | J6: =D47
B7: คงเหลือสิ้นเดือน | E7: =E4+E5-E6 | H7: การลงทุน | I7: =C56 | J7: =D56
B9: รายได้ (Income)
B10: ประเภท | C10: เป้าหมาย | D10: จริง | E10: ส่วนต่าง
B11: งานประจำ | C11: 30116 | D11: 0 | E11: =D11-C11
B12: งานเสริม / OT | C12: 0 | D12: 0 | E12: =D12-C12
B13: แม่ช่วยค่ารถ | C13: 5000 | D13: 5000 | E13: =D13-C13
E14: =D14-C14
E15: =D15-C15
E16: =D16-C16
B17: รวมรายได้ | C17: =SUM(C11:C16) | D17: =SUM(D11:D16) | E17: =D17-C17
B19: รายจ่ายประจำวัน (Daily Expense)
B20: รายการ | C20: งบ (Budget) | D20: จริง (Actual) | E20: ส่วนต่าง
B21: ค่าข้าว | C21: 0 | D21: 76 | E21: =C21-D21
B22: ค่ายาสระผม | C22: 0 | D22: 151 | E22: =C22-D22
B23: ค่าน้ำมัน | C23: 1000 | D23: 1060 | E23: =C23-D23
B24: ค่าน้ำ-ไฟหอ | C24: 800 | D24: 0 | E24: =C24-D24
E25: =C25-D25
E26: =C26-D26
E27: =C27-D27
E28: =C28-D28
E29: =C29-D29
E30: =C30-D30
B31: รวม | C31: =SUM(C21:C30) | D31: =SUM(D21:D30) | E31: =C31-D31
B33: ค่ารายเดือน / ค่าหนี้ (Subscription / Debt)
B34: รายการ | C34: งบ (Budget) | D34: จริง (Actual) | E34: ส่วนต่าง
B35: ผ่อนบัตรกสิกร | C35: 5222 | D35: 5222 | E35: =C35-D35
B36: รถ (ส่วนจ่ายเอง) | C36: 4841 | D36: 4841 | E36: =C36-D36
B37: ค่าเช่าหอใหม่ + ขยะ | C37: 3040 | D37: 3040 | E37: =C37-D37
B38: ประกันรถ 2+ | C38: 876.77 | D38: 876.77 | E38: =C38-D38
B39: เครื่องกรองน้ำ | C39: 590 | D39: 590 | E39: =C39-D39
B40: ค่าเน็ตโทรศัพท์ | C40: 416.23 | D40: 416.23 | E40: =C40-D40
B41: Claude Pro | C41: 799 | D41: 799 | E41: =C41-D41
E42: =C42-D42
E43: =C43-D43
E44: =C44-D44
E45: =C45-D45
...

Sheet ส.ค.
B2: สิงหาคม 2569
B4: ยอดยกมา (ต้นเดือน) | E4: 0 | H4: หมวด | I4: งบ | J4: จริง
B5: รายได้รวม (จริง) | E5: =D17 | H5: รายจ่ายประจำวัน | I5: =C31 | J5: =D31
B6: รายจ่ายรวม (รวมออม) | E6: =D31+D47+D56+D60 | H6: ค่ารายเดือน/หนี้ | I6: =C47 | J6: =D47
B7: คงเหลือสิ้นเดือน | E7: =E4+E5-E6 | H7: การลงทุน | I7: =C56 | J7: =D56
B9: รายได้ (Income)
B10: ประเภท | C10: เป้าหมาย | D10: จริง | E10: ส่วนต่าง
C11: 0 | D11: 0 | E11: =D11-C11
E12: =D12-C12
E13: =D13-C13
E14: =D14-C14
E15: =D15-C15
E16: =D16-C16
B17: รวมรายได้ | C17: =SUM(C11:C16) | D17: =SUM(D11:D16) | E17: =D17-C17
B19: รายจ่ายประจำวัน (Daily Expense)
B20: รายการ | C20: งบ (Budget) | D20: จริง (Actual) | E20: ส่วนต่าง
E21: =C21-D21
E22: =C22-D22
E23: =C23-D23
E24: =C24-D24
E25: =C25-D25
E26: =C26-D26
E27: =C27-D27
E28: =C28-D28
E29: =C29-D29
E30: =C30-D30
B31: รวม | C31: =SUM(C21:C30) | D31: =SUM(D21:D30) | E31: =C31-D31
B33: ค่ารายเดือน / ค่าหนี้ (Subscription / Debt)
B34: รายการ | C34: งบ (Budget) | D34: จริง (Actual) | E34: ส่วนต่าง
E35: =C35-D35
E36: =C36-D36
E37: =C37-D37
E38: =C38-D38
E39: =C39-D39
E40: =C40-D40
E41: =C41-D41
E42: =C42-D42
E43: =C43-D43
E44: =C44-D44
E45: =C45-D45
...

Sheet ก.ย.
B2: กันยายน 2569
B4: ยอดยกมา (ต้นเดือน) | E4: 0 | H4: หมวด | I4: งบ | J4: จริง
B5: รายได้รวม (จริง) | E5: =D17 | H5: รายจ่ายประจำวัน | I5: =C31 | J5: =D31
B6: รายจ่ายรวม (รวมออม) | E6: =D31+D47+D56+D60 | H6: ค่ารายเดือน/หนี้ | I6: =C47 | J6: =D47
B7: คงเหลือสิ้นเดือน | E7: =E4+E5-E6 | H7: การลงทุน | I7: =C56 | J7: =D56
B9: รายได้ (Income)
B10: ประเภท | C10: เป้าหมาย | D10: จริง | E10: ส่วนต่าง
C11: 0 | D11: 0 | E11: =D11-C11
E12: =D12-C12
E13: =D13-C13
E14: =D14-C14
E15: =D15-C15
E16: =D16-C16
B17: รวมรายได้ | C17: =SUM(C11:C16) | D17: =SUM(D11:D16) | E17: =D17-C17
B19: รายจ่ายประจำวัน (Daily Expense)
B20: รายการ | C20: งบ (Budget) | D20: จริง (Actual) | E20: ส่วนต่าง
E21: =C21-D21
E22: =C22-D22
E23: =C23-D23
E24: =C24-D24
E25: =C25-D25
E26: =C26-D26
E27: =C27-D27
E28: =C28-D28
E29: =C29-D29
E30: =C30-D30
B31: รวม | C31: =SUM(C21:C30) | D31: =SUM(D21:D30) | E31: =C31-D31
B33: ค่ารายเดือน / ค่าหนี้ (Subscription / Debt)
B34: รายการ | C34: งบ (Budget) | D34: จริง (Actual) | E34: ส่วนต่าง
E35: =C35-D35
E36: =C36-D36
E37: =C37-D37
E38: =C38-D38
E39: =C39-D39
E40: =C40-D40
E41: =C41-D41
E42: =C42-D42
E43: =C43-D43
E44: =C44-D44
E45: =C45-D45
...

Sheet ต.ค.
B2: ตุลาคม 2569
B4: ยอดยกมา (ต้นเดือน) | E4: 0 | H4: หมวด | I4: งบ | J4: จริง
B5: รายได้รวม (จริง) | E5: =D17 | H5: รายจ่ายประจำวัน | I5: =C31 | J5: =D31
B6: รายจ่ายรวม (รวมออม) | E6: =D31+D47+D56+D60 | H6: ค่ารายเดือน/หนี้ | I6: =C47 | J6: =D47
B7: คงเหลือสิ้นเดือน | E7: =E4+E5-E6 | H7: การลงทุน | I7: =C56 | J7: =D56
B9: รายได้ (Income)
B10: ประเภท | C10: เป้าหมาย | D10: จริง | E10: ส่วนต่าง
C11: 0 | D11: 0 | E11: =D11-C11
E12: =D12-C12
E13: =D13-C13
E14: =D14-C14
E15: =D15-C15
E16: =D16-C16
B17: รวมรายได้ | C17: =SUM(C11:C16) | D17: =SUM(D11:D16) | E17: =D17-C17
B19: รายจ่ายประจำวัน (Daily Expense)
B20: รายการ | C20: งบ (Budget) | D20: จริง (Actual) | E20: ส่วนต่าง
E21: =C21-D21
E22: =C22-D22
E23: =C23-D23
E24: =C24-D24
E25: =C25-D25
E26: =C26-D26
E27: =C27-D27
E28: =C28-D28
E29: =C29-D29
E30: =C30-D30
B31: รวม | C31: =SUM(C21:C30) | D31: =SUM(D21:D30) | E31: =C31-D31
B33: ค่ารายเดือน / ค่าหนี้ (Subscription / Debt)
B34: รายการ | C34: งบ (Budget) | D34: จริง (Actual) | E34: ส่วนต่าง
E35: =C35-D35
E36: =C36-D36
E37: =C37-D37
E38: =C38-D38
E39: =C39-D39
E40: =C40-D40
E41: =C41-D41
E42: =C42-D42
E43: =C43-D43
E44: =C44-D44
E45: =C45-D45
...

Sheet พ.ย.
B2: พฤศจิกายน 2569
B4: ยอดยกมา (ต้นเดือน) | E4: 0 | H4: หมวด | I4: งบ | J4: จริง
B5: รายได้รวม (จริง) | E5: =D17 | H5: รายจ่ายประจำวัน | I5: =C31 | J5: =D31
B6: รายจ่ายรวม (รวมออม) | E6: =D31+D47+D56+D60 | H6: ค่ารายเดือน/หนี้ | I6: =C47 | J6: =D47
B7: คงเหลือสิ้นเดือน | E7: =E4+E5-E6 | H7: การลงทุน | I7: =C56 | J7: =D56
B9: รายได้ (Income)
B10: ประเภท | C10: เป้าหมาย | D10: จริง | E10: ส่วนต่าง
C11: 0 | D11: 0 | E11: =D11-C11
E12: =D12-C12
E13: =D13-C13
E14: =D14-C14
E15: =D15-C15
E16: =D16-C16
B17: รวมรายได้ | C17: =SUM(C11:C16) | D17: =SUM(D11:D16) | E17: =D17-C17
B19: รายจ่ายประจำวัน (Daily Expense)
B20: รายการ | C20: งบ (Budget) | D20: จริง (Actual) | E20: ส่วนต่าง
E21: =C21-D21
E22: =C22-D22
E23: =C23-D23
E24: =C24-D24
E25: =C25-D25
E26: =C26-D26
E27: =C27-D27
E28: =C28-D28
E29: =C29-D29
E30: =C30-D30
B31: รวม | C31: =SUM(C21:C30) | D31: =SUM(D21:D30) | E31: =C31-D31
B33: ค่ารายเดือน / ค่าหนี้ (Subscription / Debt)
B34: รายการ | C34: งบ (Budget) | D34: จริง (Actual) | E34: ส่วนต่าง
E35: =C35-D35
E36: =C36-D36
E37: =C37-D37
E38: =C38-D38
E39: =C39-D39
E40: =C40-D40
E41: =C41-D41
E42: =C42-D42
E43: =C43-D43
E44: =C44-D44
E45: =C45-D45
...

Sheet ธ.ค.
B2: ธันวาคม 2569
B4: ยอดยกมา (ต้นเดือน) | E4: 0 | H4: หมวด | I4: งบ | J4: จริง
B5: รายได้รวม (จริง) | E5: =D17 | H5: รายจ่ายประจำวัน | I5: =C31 | J5: =D31
B6: รายจ่ายรวม (รวมออม) | E6: =D31+D47+D56+D60 | H6: ค่ารายเดือน/หนี้ | I6: =C47 | J6: =D47
B7: คงเหลือสิ้นเดือน | E7: =E4+E5-E6 | H7: การลงทุน | I7: =C56 | J7: =D56
B9: รายได้ (Income)
B10: ประเภท | C10: เป้าหมาย | D10: จริง | E10: ส่วนต่าง
C11: 0 | D11: 0 | E11: =D11-C11
E12: =D12-C12
E13: =D13-C13
E14: =D14-C14
E15: =D15-C15
E16: =D16-C16
B17: รวมรายได้ | C17: =SUM(C11:C16) | D17: =SUM(D11:D16) | E17: =D17-C17
B19: รายจ่ายประจำวัน (Daily Expense)
B20: รายการ | C20: งบ (Budget) | D20: จริง (Actual) | E20: ส่วนต่าง
E21: =C21-D21
E22: =C22-D22
E23: =C23-D23
E24: =C24-D24
E25: =C25-D25
E26: =C26-D26
E27: =C27-D27
E28: =C28-D28
E29: =C29-D29
E30: =C30-D30
B31: รวม | C31: =SUM(C21:C30) | D31: =SUM(D21:D30) | E31: =C31-D31
B33: ค่ารายเดือน / ค่าหนี้ (Subscription / Debt)
B34: รายการ | C34: งบ (Budget) | D34: จริง (Actual) | E34: ส่วนต่าง
E35: =C35-D35
E36: =C36-D36
E37: =C37-D37
E38: =C38-D38
E39: =C39-D39
E40: =C40-D40
E41: =C41-D41
E42: =C42-D42
E43: =C43-D43
E44: =C44-D44
E45: =C45-D45
...

Sheet ทรัพย์สิน
B2: ทรัพย์สิน & ความมั่งคั่งสุทธิ (Net Worth)
B4: ทรัพย์สิน (Assets)
B5: รายการ | C5: ประเภท | D5: มูลค่า | E5: หมายเหตุ
B6: เงินประกันหอใหม่ | C6: เงินมัดจำ | D6: 2000 | E6: ได้คืนตอนย้ายออก
B7: เงินสด / เงินฝาก | C7: เงินสด | D7: 0 | E7: กรอกยอดจริง
B8: กองทุนรวม | C8: การลงทุน | D8: 0 | E8: ถ้ามี
B9: รถยนต์ (Civic) | C9: ยานพาหนะ | D9: 0 | E9: มูลค่าปัจจุบัน
B10: รวมทรัพย์สิน | D10: =SUM(D6:D9)
B12: หนี้สินคงเหลือ (Liabilities)
B13: รายการ | C13: ต่อเดือน | D13: งวดเหลือ | E13: ยอดหนี้คงเหลือ
B14: ผ่อนบัตรกสิกร | C14: 5222 | D14: 5 | E14: =C14*D14
B15: รถ (ยอดเต็ม) | C15: 9841 | D15: 48 | E15: =C15*D15
B16: ประกันรถ 2+ | C16: 876.77 | D16: 6 | E16: =C16*D16
B17: เครื่องกรองน้ำ | C17: 590 | D17: 67 | E17: =C17*D17
B18: รวมหนี้สิน | E18: =SUM(E14:E17)
B20: ความมั่งคั่งสุทธิ (Net Worth) | E20: =D10-E18
